2023-09-30 22:39:10.367 | INFO     | __main__:<module>:19 - database connected successfully
2023-09-30 22:39:21.122 | ERROR    | bot.core.handlers.admin:add_admin_menu:235 - list index out of range
2023-09-30 22:39:46.333 | ERROR    | bot.core.handlers.admin:add_admin_menu:235 - list index out of range
2023-09-30 22:42:26.907 | INFO     | __main__:<module>:19 - database connected successfully
2023-09-30 22:43:11.838 | ERROR    | bot.core.db.admin_actions:get_admin_by_id:22 - Admin with telegram id = Отменить was not found in DB
2023-09-30 22:43:31.884 | ERROR    | bot.core.handlers.admin:add_admin_menu:235 - list index out of range
2023-09-30 22:45:21.655 | INFO     | __main__:<module>:19 - database connected successfully
2023-10-01 18:26:29.780 | ERROR    | bot.core.db.client_actions:get_start_client_by_tg_id:55 - Client with telegram id = 1648914934 was not found in DB
2023-10-01 18:26:29.781 | ERROR    | bot.core.handlers.users:start_command:54 - 'NoneType' object has no attribute 'phone_number'
2023-10-01 18:26:29.781 | INFO     | bot.core.handlers.users:start_command:55 - {'telegram_id': 1648914934, 'name': 'Надежда', 'username': 'Nadi_Turtygina'} was added to database
2023-10-01 21:49:26.533 | ERROR    | bot.core.db.client_actions:get_start_client_by_tg_id:55 - Client with telegram id = 555698411 was not found in DB
2023-10-01 21:49:26.534 | ERROR    | bot.core.handlers.users:start_command:54 - 'NoneType' object has no attribute 'phone_number'
2023-10-01 21:49:26.534 | INFO     | bot.core.handlers.users:start_command:55 - {'telegram_id': 555698411, 'name': 'Вера', 'username': 'krverav'} was added to database
2023-10-02 02:39:15.367 | ERROR    | bot.core.db.client_actions:get_start_client_by_tg_id:55 - Client with telegram id = 1732766060 was not found in DB
2023-10-02 02:39:15.368 | ERROR    | bot.core.handlers.users:start_command:54 - 'NoneType' object has no attribute 'phone_number'
2023-10-02 02:39:15.368 | INFO     | bot.core.handlers.users:start_command:55 - {'telegram_id': 1732766060, 'name': 'Mikki', 'username': 'jiizn_oplk'} was added to database
2023-10-02 09:40:40.736 | ERROR    | bot.core.db.client_actions:get_start_client_by_tg_id:55 - Client with telegram id = 1011020633 was not found in DB
2023-10-02 09:40:40.736 | ERROR    | bot.core.handlers.users:start_command:54 - 'NoneType' object has no attribute 'phone_number'
2023-10-02 09:40:40.736 | INFO     | bot.core.handlers.users:start_command:55 - {'telegram_id': 1011020633, 'name': 'Ulia', 'username': None} was added to database
2023-10-02 11:19:52.456 | ERROR    | bot.core.db.client_actions:get_start_client_by_tg_id:55 - Client with telegram id = 715305186 was not found in DB
2023-10-02 11:19:52.458 | ERROR    | bot.core.handlers.users:start_command:54 - 'NoneType' object has no attribute 'phone_number'
2023-10-02 11:19:52.458 | INFO     | bot.core.handlers.users:start_command:55 - {'telegram_id': 715305186, 'name': 'Виктория', 'username': 'BaeVikt'} was added to database
2023-10-02 12:50:10.922 | ERROR    | bot.core.db.client_actions:get_start_client_by_tg_id:55 - Client with telegram id = 860177255 was not found in DB
2023-10-02 12:50:10.923 | ERROR    | bot.core.handlers.users:start_command:54 - 'NoneType' object has no attribute 'phone_number'
2023-10-02 12:50:10.923 | INFO     | bot.core.handlers.users:start_command:55 - {'telegram_id': 860177255, 'name': 'BAKLASHIK', 'username': 'PUNKY_HOI_The_Victory_Is_Ours'} was added to database
2023-10-02 17:30:22.504 | ERROR    | bot.core.db.client_actions:get_start_client_by_tg_id:55 - Client with telegram id = 452722040 was not found in DB
2023-10-02 17:30:22.505 | ERROR    | bot.core.handlers.users:start_command:54 - 'NoneType' object has no attribute 'phone_number'
2023-10-02 17:30:22.505 | INFO     | bot.core.handlers.users:start_command:55 - {'telegram_id': 452722040, 'name': 'Julia', 'username': 'Aaandreeva'} was added to database
2023-10-02 20:43:40.859 | INFO     | bot.core.handlers.admin:enter_event_picture:368 - [Errno 2] No such file or directory: 'sources/events/Суббота.mp4'
/root/SmokeDog/venv/lib/python3.9/site-packages/aiogram/types/mixins.py:40: DeprecationWarning: destination parameter is deprecated, please use destination_dir or destination_file.
  warn_deprecated(
2023-10-02 21:24:42.639 | ERROR    | bot.core.db.client_actions:get_start_client_by_tg_id:55 - Client with telegram id = 724709486 was not found in DB
2023-10-02 21:24:42.640 | ERROR    | bot.core.handlers.users:start_command:54 - 'NoneType' object has no attribute 'phone_number'
2023-10-02 21:24:42.640 | INFO     | bot.core.handlers.users:start_command:55 - {'telegram_id': 724709486, 'name': 'Кристина', 'username': 'MashkovaKristina'} was added to database
2023-10-02 23:45:04.714 | ERROR    | bot.core.db.client_actions:get_start_client_by_tg_id:55 - Client with telegram id = 433965876 was not found in DB
2023-10-02 23:45:04.715 | ERROR    | bot.core.handlers.users:start_command:54 - 'NoneType' object has no attribute 'phone_number'
2023-10-02 23:45:04.715 | INFO     | bot.core.handlers.users:start_command:55 - {'telegram_id': 433965876, 'name': 'Natali', 'username': 'Natali_Petra'} was added to database
2023-10-03 16:07:28.449 | ERROR    | bot.core.db.client_actions:get_start_client_by_tg_id:55 - Client with telegram id = 944737157 was not found in DB
2023-10-03 16:07:28.450 | ERROR    | bot.core.handlers.users:start_command:54 - 'NoneType' object has no attribute 'phone_number'
2023-10-03 16:07:28.451 | INFO     | bot.core.handlers.users:start_command:55 - {'telegram_id': 944737157, 'name': 'Olya', 'username': 'o_lyalu'} was added to database
2023-10-03 16:08:28.963 | INFO     | bot.core.handlers.admin:enter_event_picture:368 - [Errno 2] No such file or directory: 'sources/events/Пятница.mp4'
/root/SmokeDog/venv/lib/python3.9/site-packages/aiogram/types/mixins.py:40: DeprecationWarning: destination parameter is deprecated, please use destination_dir or destination_file.
  warn_deprecated(
2023-10-03 16:52:34.714 | ERROR    | bot.core.db.client_actions:get_start_client_by_tg_id:55 - Client with telegram id = 223188648 was not found in DB
2023-10-03 16:52:34.714 | ERROR    | bot.core.handlers.users:start_command:54 - 'NoneType' object has no attribute 'phone_number'
2023-10-03 16:52:34.715 | INFO     | bot.core.handlers.users:start_command:55 - {'telegram_id': 223188648, 'name': 'A', 'username': 'Al_Gi'} was added to database
2023-10-03 17:22:29.218 | ERROR    | bot.core.db.client_actions:get_start_client_by_tg_id:55 - Client with telegram id = 895178507 was not found in DB
2023-10-03 17:22:29.219 | ERROR    | bot.core.handlers.users:start_command:54 - 'NoneType' object has no attribute 'phone_number'
2023-10-03 17:22:29.220 | INFO     | bot.core.handlers.users:start_command:55 - {'telegram_id': 895178507, 'name': 'Дарья', 'username': 'doctor_gudkova'} was added to database
Cause exception while getting updates.
Traceback (most recent call last):
  File "/root/SmokeDog/venv/lib/python3.9/site-packages/aiogram/dispatcher/dispatcher.py", line 381, in start_polling
    updates = await self.bot.get_updates(
  File "/root/SmokeDog/venv/lib/python3.9/site-packages/aiogram/bot/bot.py", line 110, in get_updates
    result = await self.request(api.Methods.GET_UPDATES, payload)
  File "/root/SmokeDog/venv/lib/python3.9/site-packages/aiogram/bot/base.py", line 236, in request
    return await api.make_request(await self.get_session(), self.server, self.__token, method, data, files,
  File "/root/SmokeDog/venv/lib/python3.9/site-packages/aiogram/bot/api.py", line 139, in make_request
    async with session.post(url, data=req, **kwargs) as response:
  File "/root/SmokeDog/venv/lib/python3.9/site-packages/aiohttp/client.py", line 1141, in __aenter__
    self._resp = await self._coro
  File "/root/SmokeDog/venv/lib/python3.9/site-packages/aiohttp/client.py", line 560, in _request
    await resp.start(conn)
  File "/root/SmokeDog/venv/lib/python3.9/site-packages/aiohttp/client_reqrep.py", line 914, in start
    self._continue = None
  File "/root/SmokeDog/venv/lib/python3.9/site-packages/aiohttp/helpers.py", line 721, in __exit__
    raise asyncio.TimeoutError from None
asyncio.exceptions.TimeoutError
2023-10-03 18:29:54.651 | ERROR    | bot.core.db.client_actions:get_start_client_by_tg_id:55 - Client with telegram id = 353197666 was not found in DB
2023-10-03 18:29:54.652 | ERROR    | bot.core.handlers.users:start_command:54 - 'NoneType' object has no attribute 'phone_number'
2023-10-03 18:29:54.652 | INFO     | bot.core.handlers.users:start_command:55 - {'telegram_id': 353197666, 'name': 'Нелли', 'username': 'Nelly_p86'} was added to database
2023-10-03 20:53:31.558 | ERROR    | bot.core.db.client_actions:get_start_client_by_tg_id:55 - Client with telegram id = 1072645090 was not found in DB
2023-10-03 20:53:31.558 | ERROR    | bot.core.handlers.users:start_command:54 - 'NoneType' object has no attribute 'phone_number'
2023-10-03 20:53:31.559 | INFO     | bot.core.handlers.users:start_command:55 - {'telegram_id': 1072645090, 'name': 'g0yar', 'username': 'g0yar'} was added to database
2023-10-03 22:21:21.456 | INFO     | __main__:<module>:19 - database connected successfully
2023-10-03 22:24:45.251 | INFO     | __main__:<module>:19 - database connected successfully
2023-10-04 01:50:26.291 | ERROR    | bot.core.db.client_actions:get_start_client_by_tg_id:55 - Client with telegram id = 457135255 was not found in DB
2023-10-04 01:50:26.292 | ERROR    | bot.core.handlers.users:start_command:54 - 'NoneType' object has no attribute 'phone_number'
2023-10-04 01:50:26.292 | INFO     | bot.core.handlers.users:start_command:55 - {'telegram_id': 457135255, 'name': 'Ekaterina', 'username': None} was added to database
2023-10-04 06:40:50.612 | ERROR    | bot.core.db.client_actions:get_start_client_by_tg_id:55 - Client with telegram id = 5063935422 was not found in DB
2023-10-04 06:40:50.612 | ERROR    | bot.core.handlers.users:start_command:54 - 'NoneType' object has no attribute 'phone_number'
2023-10-04 06:40:50.613 | INFO     | bot.core.handlers.users:start_command:55 - {'telegram_id': 5063935422, 'name': 'ROX', 'username': 'ontheroxxx'} was added to database
2023-10-04 10:53:08.914 | ERROR    | bot.core.db.client_actions:get_start_client_by_tg_id:55 - Client with telegram id = 60341573 was not found in DB
2023-10-04 10:53:08.915 | ERROR    | bot.core.handlers.users:start_command:54 - 'NoneType' object has no attribute 'phone_number'
2023-10-04 10:53:08.915 | INFO     | bot.core.handlers.users:start_command:55 - {'telegram_id': 60341573, 'name': '🦈111', 'username': 'Geray111'} was added to database
2023-10-04 11:17:37.191 | ERROR    | bot.core.db.client_actions:get_start_client_by_tg_id:55 - Client with telegram id = 611596803 was not found in DB
2023-10-04 11:17:37.192 | ERROR    | bot.core.handlers.users:start_command:54 - 'NoneType' object has no attribute 'phone_number'
2023-10-04 11:17:37.192 | INFO     | bot.core.handlers.users:start_command:55 - {'telegram_id': 611596803, 'name': 'Anabella', 'username': 'anabella_tomson'} was added to database
2023-10-04 11:50:10.273 | ERROR    | bot.core.db.client_actions:get_start_client_by_tg_id:55 - Client with telegram id = 443541408 was not found in DB
2023-10-04 11:50:10.274 | ERROR    | bot.core.handlers.users:start_command:54 - 'NoneType' object has no attribute 'phone_number'
2023-10-04 11:50:10.274 | INFO     | bot.core.handlers.users:start_command:55 - {'telegram_id': 443541408, 'name': 'Катерина', 'username': 'Who_is_Katherine'} was added to database
2023-10-04 11:58:32.909 | ERROR    | bot.core.db.client_actions:get_start_client_by_tg_id:55 - Client with telegram id = 1442922325 was not found in DB
2023-10-04 11:58:32.910 | ERROR    | bot.core.handlers.users:start_command:54 - 'NoneType' object has no attribute 'phone_number'
2023-10-04 11:58:32.910 | INFO     | bot.core.handlers.users:start_command:55 - {'telegram_id': 1442922325, 'name': 'Angelina', 'username': None} was added to database
2023-10-04 16:02:04.131 | INFO     | __main__:<module>:19 - database connected successfully
2023-10-04 16:08:20.330 | INFO     | __main__:<module>:19 - database connected successfully
Task exception was never retrieved
future: <Task finished name='Task-28' coro=<Dispatcher._process_polling_updates() done, defined at /root/SmokeDog/venv/lib/python3.9/site-packages/aiogram/dispatcher/dispatcher.py:407> exception=BadRequest("Inline keyboard button url 'https://tg://user?id=5384004606' is invalid: wrong port number specified in the url")>
Traceback (most recent call last):
  File "/root/SmokeDog/venv/lib/python3.9/site-packages/aiogram/dispatcher/dispatcher.py", line 415, in _process_polling_updates
    for responses in itertools.chain.from_iterable(await self.process_updates(updates, fast)):
  File "/root/SmokeDog/venv/lib/python3.9/site-packages/aiogram/dispatcher/dispatcher.py", line 235, in process_updates
    return await asyncio.gather(*tasks)
  File "/root/SmokeDog/venv/lib/python3.9/site-packages/aiogram/dispatcher/handler.py", line 117, in notify
    response = await handler_obj.handler(*args, **partial_data)
  File "/root/SmokeDog/venv/lib/python3.9/site-packages/aiogram/dispatcher/dispatcher.py", line 256, in process_update
    return await self.message_handlers.notify(update.message)
  File "/root/SmokeDog/venv/lib/python3.9/site-packages/aiogram/dispatcher/handler.py", line 117, in notify
    response = await handler_obj.handler(*args, **partial_data)
  File "/root/SmokeDog/./bot/core/handlers/users.py", line 344, in enter_time
    await bot.send_message(text=booking_msg, chat_id=chat_id, reply_markup=markup)
  File "/root/SmokeDog/venv/lib/python3.9/site-packages/aiogram/bot/bot.py", line 346, in send_message
    result = await self.request(api.Methods.SEND_MESSAGE, payload)
  File "/root/SmokeDog/venv/lib/python3.9/site-packages/aiogram/bot/base.py", line 236, in request
    return await api.make_request(await self.get_session(), self.server, self.__token, method, data, files,
  File "/root/SmokeDog/venv/lib/python3.9/site-packages/aiogram/bot/api.py", line 140, in make_request
    return check_result(method, response.content_type, response.status, await response.text())
  File "/root/SmokeDog/venv/lib/python3.9/site-packages/aiogram/bot/api.py", line 115, in check_result
    exceptions.BadRequest.detect(description)
  File "/root/SmokeDog/venv/lib/python3.9/site-packages/aiogram/utils/exceptions.py", line 141, in detect
    raise cls(description)
aiogram.utils.exceptions.BadRequest: Inline keyboard button url 'https://tg://user?id=5384004606' is invalid: wrong port number specified in the url
2023-10-04 16:10:00.037 | INFO     | __main__:<module>:19 - database connected successfully
Task exception was never retrieved
future: <Task finished name='Task-7' coro=<Dispatcher._process_polling_updates() done, defined at /root/SmokeDog/venv/lib/python3.9/site-packages/aiogram/dispatcher/dispatcher.py:407> exception=BadRequest("Inline keyboard button url 'https://tg://user?id=5384004606' is invalid: wrong port number specified in the url")>
Traceback (most recent call last):
  File "/root/SmokeDog/venv/lib/python3.9/site-packages/aiogram/dispatcher/dispatcher.py", line 415, in _process_polling_updates
    for responses in itertools.chain.from_iterable(await self.process_updates(updates, fast)):
  File "/root/SmokeDog/venv/lib/python3.9/site-packages/aiogram/dispatcher/dispatcher.py", line 235, in process_updates
    return await asyncio.gather(*tasks)
  File "/root/SmokeDog/venv/lib/python3.9/site-packages/aiogram/dispatcher/handler.py", line 117, in notify
    response = await handler_obj.handler(*args, **partial_data)
  File "/root/SmokeDog/venv/lib/python3.9/site-packages/aiogram/dispatcher/dispatcher.py", line 256, in process_update
    return await self.message_handlers.notify(update.message)
  File "/root/SmokeDog/venv/lib/python3.9/site-packages/aiogram/dispatcher/handler.py", line 117, in notify
    response = await handler_obj.handler(*args, **partial_data)
  File "/root/SmokeDog/./bot/core/handlers/users.py", line 344, in enter_time
    await bot.send_message(text=booking_msg, chat_id=chat_id, reply_markup=markup)
  File "/root/SmokeDog/venv/lib/python3.9/site-packages/aiogram/bot/bot.py", line 346, in send_message
    result = await self.request(api.Methods.SEND_MESSAGE, payload)
  File "/root/SmokeDog/venv/lib/python3.9/site-packages/aiogram/bot/base.py", line 236, in request
    return await api.make_request(await self.get_session(), self.server, self.__token, method, data, files,
  File "/root/SmokeDog/venv/lib/python3.9/site-packages/aiogram/bot/api.py", line 140, in make_request
    return check_result(method, response.content_type, response.status, await response.text())
  File "/root/SmokeDog/venv/lib/python3.9/site-packages/aiogram/bot/api.py", line 115, in check_result
    exceptions.BadRequest.detect(description)
  File "/root/SmokeDog/venv/lib/python3.9/site-packages/aiogram/utils/exceptions.py", line 141, in detect
    raise cls(description)
aiogram.utils.exceptions.BadRequest: Inline keyboard button url 'https://tg://user?id=5384004606' is invalid: wrong port number specified in the url
Task exception was never retrieved
future: <Task finished name='Task-15' coro=<Dispatcher._process_polling_updates() done, defined at /root/SmokeDog/venv/lib/python3.9/site-packages/aiogram/dispatcher/dispatcher.py:407> exception=BadRequest("Inline keyboard button url 'https://tg://user?id=5384004606' is invalid: wrong port number specified in the url")>
Traceback (most recent call last):
  File "/root/SmokeDog/venv/lib/python3.9/site-packages/aiogram/dispatcher/dispatcher.py", line 415, in _process_polling_updates
    for responses in itertools.chain.from_iterable(await self.process_updates(updates, fast)):
  File "/root/SmokeDog/venv/lib/python3.9/site-packages/aiogram/dispatcher/dispatcher.py", line 235, in process_updates
    return await asyncio.gather(*tasks)
  File "/root/SmokeDog/venv/lib/python3.9/site-packages/aiogram/dispatcher/handler.py", line 117, in notify
    response = await handler_obj.handler(*args, **partial_data)
  File "/root/SmokeDog/venv/lib/python3.9/site-packages/aiogram/dispatcher/dispatcher.py", line 256, in process_update
    return await self.message_handlers.notify(update.message)
  File "/root/SmokeDog/venv/lib/python3.9/site-packages/aiogram/dispatcher/handler.py", line 117, in notify
    response = await handler_obj.handler(*args, **partial_data)
  File "/root/SmokeDog/./bot/core/handlers/users.py", line 344, in enter_time
    await bot.send_message(text=booking_msg, chat_id=chat_id, reply_markup=markup)
  File "/root/SmokeDog/venv/lib/python3.9/site-packages/aiogram/bot/bot.py", line 346, in send_message
    result = await self.request(api.Methods.SEND_MESSAGE, payload)
  File "/root/SmokeDog/venv/lib/python3.9/site-packages/aiogram/bot/base.py", line 236, in request
    return await api.make_request(await self.get_session(), self.server, self.__token, method, data, files,
  File "/root/SmokeDog/venv/lib/python3.9/site-packages/aiogram/bot/api.py", line 140, in make_request
    return check_result(method, response.content_type, response.status, await response.text())
  File "/root/SmokeDog/venv/lib/python3.9/site-packages/aiogram/bot/api.py", line 115, in check_result
    exceptions.BadRequest.detect(description)
  File "/root/SmokeDog/venv/lib/python3.9/site-packages/aiogram/utils/exceptions.py", line 141, in detect
    raise cls(description)
aiogram.utils.exceptions.BadRequest: Inline keyboard button url 'https://tg://user?id=5384004606' is invalid: wrong port number specified in the url
Task exception was never retrieved
future: <Task finished name='Task-21' coro=<Dispatcher._process_polling_updates() done, defined at /root/SmokeDog/venv/lib/python3.9/site-packages/aiogram/dispatcher/dispatcher.py:407> exception=BadRequest("Inline keyboard button url 'https://tg://user?id=5384004606' is invalid: wrong port number specified in the url")>
Traceback (most recent call last):
  File "/root/SmokeDog/venv/lib/python3.9/site-packages/aiogram/dispatcher/dispatcher.py", line 415, in _process_polling_updates
    for responses in itertools.chain.from_iterable(await self.process_updates(updates, fast)):
  File "/root/SmokeDog/venv/lib/python3.9/site-packages/aiogram/dispatcher/dispatcher.py", line 235, in process_updates
    return await asyncio.gather(*tasks)
  File "/root/SmokeDog/venv/lib/python3.9/site-packages/aiogram/dispatcher/handler.py", line 117, in notify
    response = await handler_obj.handler(*args, **partial_data)
  File "/root/SmokeDog/venv/lib/python3.9/site-packages/aiogram/dispatcher/dispatcher.py", line 256, in process_update
    return await self.message_handlers.notify(update.message)
  File "/root/SmokeDog/venv/lib/python3.9/site-packages/aiogram/dispatcher/handler.py", line 117, in notify
    response = await handler_obj.handler(*args, **partial_data)
  File "/root/SmokeDog/./bot/core/handlers/users.py", line 344, in enter_time
    await bot.send_message(text=booking_msg, chat_id=chat_id, reply_markup=markup)
  File "/root/SmokeDog/venv/lib/python3.9/site-packages/aiogram/bot/bot.py", line 346, in send_message
    result = await self.request(api.Methods.SEND_MESSAGE, payload)
  File "/root/SmokeDog/venv/lib/python3.9/site-packages/aiogram/bot/base.py", line 236, in request
    return await api.make_request(await self.get_session(), self.server, self.__token, method, data, files,
  File "/root/SmokeDog/venv/lib/python3.9/site-packages/aiogram/bot/api.py", line 140, in make_request
    return check_result(method, response.content_type, response.status, await response.text())
  File "/root/SmokeDog/venv/lib/python3.9/site-packages/aiogram/bot/api.py", line 115, in check_result
    exceptions.BadRequest.detect(description)
  File "/root/SmokeDog/venv/lib/python3.9/site-packages/aiogram/utils/exceptions.py", line 141, in detect
    raise cls(description)
aiogram.utils.exceptions.BadRequest: Inline keyboard button url 'https://tg://user?id=5384004606' is invalid: wrong port number specified in the url
Task exception was never retrieved
future: <Task finished name='Task-27' coro=<Dispatcher._process_polling_updates() done, defined at /root/SmokeDog/venv/lib/python3.9/site-packages/aiogram/dispatcher/dispatcher.py:407> exception=BadRequest("Inline keyboard button url 'https://tg://user?id=5384004606' is invalid: wrong port number specified in the url")>
Traceback (most recent call last):
  File "/root/SmokeDog/venv/lib/python3.9/site-packages/aiogram/dispatcher/dispatcher.py", line 415, in _process_polling_updates
    for responses in itertools.chain.from_iterable(await self.process_updates(updates, fast)):
  File "/root/SmokeDog/venv/lib/python3.9/site-packages/aiogram/dispatcher/dispatcher.py", line 235, in process_updates
    return await asyncio.gather(*tasks)
  File "/root/SmokeDog/venv/lib/python3.9/site-packages/aiogram/dispatcher/handler.py", line 117, in notify
    response = await handler_obj.handler(*args, **partial_data)
  File "/root/SmokeDog/venv/lib/python3.9/site-packages/aiogram/dispatcher/dispatcher.py", line 256, in process_update
    return await self.message_handlers.notify(update.message)
  File "/root/SmokeDog/venv/lib/python3.9/site-packages/aiogram/dispatcher/handler.py", line 117, in notify
    response = await handler_obj.handler(*args, **partial_data)
  File "/root/SmokeDog/./bot/core/handlers/users.py", line 344, in enter_time
    await bot.send_message(text=booking_msg, chat_id=chat_id, reply_markup=markup)
  File "/root/SmokeDog/venv/lib/python3.9/site-packages/aiogram/bot/bot.py", line 346, in send_message
    result = await self.request(api.Methods.SEND_MESSAGE, payload)
  File "/root/SmokeDog/venv/lib/python3.9/site-packages/aiogram/bot/base.py", line 236, in request
    return await api.make_request(await self.get_session(), self.server, self.__token, method, data, files,
  File "/root/SmokeDog/venv/lib/python3.9/site-packages/aiogram/bot/api.py", line 140, in make_request
    return check_result(method, response.content_type, response.status, await response.text())
  File "/root/SmokeDog/venv/lib/python3.9/site-packages/aiogram/bot/api.py", line 115, in check_result
    exceptions.BadRequest.detect(description)
  File "/root/SmokeDog/venv/lib/python3.9/site-packages/aiogram/utils/exceptions.py", line 141, in detect
    raise cls(description)
aiogram.utils.exceptions.BadRequest: Inline keyboard button url 'https://tg://user?id=5384004606' is invalid: wrong port number specified in the url
